[2021-05-23 18:45:34 +0200] [6479] [INFO] Starting gunicorn 20.1.0
[2021-05-23 18:45:34 +0200] [6479] [INFO] Listening at: http://127.0.0.1:5000 (6479)
[2021-05-23 18:45:34 +0200] [6479] [INFO] Using worker: sync
[2021-05-23 18:45:34 +0200] [6564] [INFO] Booting worker with pid: 6564
[2021-05-23 18:54:09,995] ERROR in app: Exception on /files/add/ [POST]
Traceback (most recent call last):
  File "/home/elie/.pyenv/versions/3.9.5/lib/python3.9/site-packages/flask/app.py", line 2051, in wsgi_app
    response = self.full_dispatch_request()
  File "/home/elie/.pyenv/versions/3.9.5/lib/python3.9/site-packages/flask/app.py", line 1501, in full_dispatch_request
    rv = self.handle_user_exception(e)
  File "/home/elie/.pyenv/versions/3.9.5/lib/python3.9/site-packages/flask/app.py", line 1499, in full_dispatch_request
    rv = self.dispatch_request()
  File "/home/elie/.pyenv/versions/3.9.5/lib/python3.9/site-packages/flask/app.py", line 1485, in dispatch_request
    return self.ensure_sync(self.view_functions[rule.endpoint])(**req.view_args)
  File "/home/elie/pythonprojects/website/app/__init__.py", line 113, in imma_upload_ur_mother
    file.save(os.path.join(app.config["UPLOAD_FOLDER"], filename))
  File "/home/elie/.pyenv/versions/3.9.5/lib/python3.9/site-packages/werkzeug/datastructures.py", line 3013, in save
    dst = open(dst, "wb")
FileNotFoundError: [Errno 2] No such file or directory: '/home/elie/Documents/usb/FILE_6268.pdf'
[2021-05-23 22:12:28 +0200] [6479] [CRITICAL] WORKER TIMEOUT (pid:6564)
[2021-05-23 22:12:30 +0200] [6564] [INFO] Worker exiting (pid: 6564)
[2021-05-23 22:12:30 +0200] [17291] [INFO] Booting worker with pid: 17291
